Workbook

Sheet CONTROLE
A1: CONTROLE DE DIÁRIAS.
A3: HÓSPEDES | B3: CLASSE | C3: VALOR | D3: ENTRADA | E3: SAÍDA | F3: QTE. DIÁRIAS | G3: SUBTOTAL | H3: DECONTO | I3: FRIGOBAR | J3: TOTAL | S3: Antônio da Silva
A4: Gilberto Lacerda | B4: PRESIDENCIAL | C4: =VLOOKUP(B4,CLASSES!$A$3:$B$8,2,FALSE) -> 380 | D4: 46113 | E4: 46114 | F4: =E4-D4 -> 1 | G4: =C4*F4 -> 380 | H4: =IF(AND(B4="PRESIDENCIAL",F4>4),G4*0.2,0) -> 0 | I4: 30 | J4: =G4-H4+I4 -> 410 | S4: Bruno de Matos
A5: João Silva | B5: POPULAR | C5: =VLOOKUP(B5,CLASSES!$A$3:$B$8,2,FALSE) -> 90 | D5: 46113 | E5: 46115 | F5: =E5-D5 -> 2 | G5: =C5*F5 -> 180 | H5: =IF(AND(B5="PRESIDENCIAL",F5>4),G5*0.2,0) -> 0 | I5: 52 | J5: =G5-H5+I5 -> 232 | S5: Camille Ventura
A6: Maria Souza | B6: STANDART | C6: =VLOOKUP(B6,CLASSES!$A$3:$B$8,2,FALSE) -> 110 | D6: 46113 | E6: 46116 | F6: =E6-D6 -> 3 | G6: =C6*F6 -> 330 | H6: =IF(AND(B6="PRESIDENCIAL",F6>4),G6*0.2,0) -> 0 | I6: 0 | J6: =G6-H6+I6 -> 330 | S6: Daniel Leite
A7: Leonardo Tavares | B7: ALTA | C7: =VLOOKUP(B7,CLASSES!$A$3:$B$8,2,FALSE) -> 120 | D7: 46113 | E7: 46114 | F7: =E7-D7 -> 1 | G7: =C7*F7 -> 120 | H7: =IF(AND(B7="PRESIDENCIAL",F7>4),G7*0.2,0) -> 0 | I7: 10 | J7: =G7-H7+I7 -> 130 | S7: Davi Tonni
A8: TANIA | B8: DOUBLE | C8: =VLOOKUP(B8,CLASSES!$A$3:$B$8,2,FALSE) -> 240 | D8: 46114 | E8: 46117 | F8: =E8-D8 -> 3 | G8: =C8*F8 -> 720 | H8: =IF(AND(B8="PRESIDENCIAL",F8>4),G8*0.2,0) -> 0 | I8: 25 | J8: =G8-H8+I8 -> 745 | S8: Eduardo Filho
A9: Heloísa Teles | B9: EXECUTIVA | C9: =VLOOKUP(B9,CLASSES!$A$3:$B$8,2,FALSE) -> 170 | D9: 46114 | E9: 46115 | F9: =E9-D9 -> 1 | G9: =C9*F9 -> 170 | H9: =IF(AND(B9="PRESIDENCIAL",F9>4),G9*0.2,0) -> 0 | I9: 35 | J9: =G9-H9+I9 -> 205 | S9: Elisa Ferrari
A10: Carlos Pereira | B10: ALTA | C10: =VLOOKUP(B10,CLASSES!$A$3:$B$8,2,FALSE) -> 120 | D10: 46114 | E10: 46118 | F10: =E10-D10 -> 4 | G10: =C10*F10 -> 480 | H10: =IF(AND(B10="PRESIDENCIAL",F10>4),G10*0.2,0) -> 0 | I10: 30 | J10: =G10-H10+I10 -> 510 | S10: Eric Dias
A11: Ana Oliveira | B11: EXECUTIVA | C11: =VLOOKUP(B11,CLASSES!$A$3:$B$8,2,FALSE) -> 170 | D11: 46114 | E11: 46117 | F11: =E11-D11 -> 3 | G11: =C11*F11 -> 510 | H11: =IF(AND(B11="PRESIDENCIAL",F11>4),G11*0.2,0) -> 0 | I11: 30 | J11: =G11-H11+I11 -> 540 | S11: Gustavo Silva
A12: Juliana Mendes | B12: EXECUTIVA | C12: =VLOOKUP(B12,CLASSES!$A$3:$B$8,2,FALSE) -> 170 | D12: 46114 | E12: 46115 | F12: =E12-D12 -> 1 | G12: =C12*F12 -> 170 | H12: =IF(AND(B12="PRESIDENCIAL",F12>4),G12*0.2,0) -> 0 | I12: 50 | J12: =G12-H12+I12 -> 220 | S12: Gustavo Filho
A13: Marco Aurélio | B13: POPULAR | C13: =VLOOKUP(B13,CLASSES!$A$3:$B$8,2,FALSE) -> 90 | D13: 46115 | E13: 46119 | F13: =E13-D13 -> 4 | G13: =C13*F13 -> 360 | H13: =IF(AND(B13="PRESIDENCIAL",F13>4),G13*0.2,0) -> 0 | I13: 0 | J13: =G13-H13+I13 -> 360 | S13: Gustavo Minatto
A14: Ismael Batista | B14: STANDART | C14: =VLOOKUP(B14,CLASSES!$A$3:$B$8,2,FALSE) -> 110 | D14: 46115 | E14: 46116 | F14: =E14-D14 -> 1 | G14: =C14*F14 -> 110 | H14: =IF(AND(B14="PRESIDENCIAL",F14>4),G14*0.2,0) -> 0 | I14: 5 | J14: =G14-H14+I14 -> 115 | S14: Heloíse Kisner
A15: Pedro Santos | B15: DOUBLE | C15: =VLOOKUP(B15,CLASSES!$A$3:$B$8,2,FALSE) -> 240 | D15: 46115 | E15: 46119 | F15: =E15-D15 -> 4 | G15: =C15*F15 -> 960 | H15: =IF(AND(B15="PRESIDENCIAL",F15>4),G15*0.2,0) -> 0 | I15: 0 | J15: =G15-H15+I15 -> 960 | S15: Bruno de Matos
... A25: Bruno Teixeira | B25: POPULAR | C25: =VLOOKUP(B25,CLASSES!$A$3:$B$8,2,FALSE) -> 90 | D25: 46117 | E25: 46118 | F25: =E25-D25 -> 1 | G25: =C25*F25 -> 90 | H25: =IF(AND(B25="PRESIDENCIAL",F25>4),G25*0.2,0) -> 0 | I25: 25 | J25: =G25-H25+I25 -> 115 | S25: Heloíse Kisner
A26: Lídia Fagundes | B26: DOUBLE | C26: =VLOOKUP(B26,CLASSES!$A$3:$B$8,2,FALSE) -> 240 | D26: 46118 | E26: 46119 | F26: =E26-D26 -> 1 | G26: =C26*F26 -> 240 | H26: =IF(AND(B26="PRESIDENCIAL",F26>4),G26*0.2,0) -> 0 | I26: 0 | J26: =G26-H26+I26 -> 240
A27: Bruno Ribeiro | B27: DOUBLE | C27: =VLOOKUP(B27,CLASSES!$A$3:$B$8,2,FALSE) -> 240 | D27: 46118 | E27: 46123 | F27: =E27-D27 -> 5 | G27: =C27*F27 -> 1200 | H27: =IF(AND(B27="PRESIDENCIAL",F27>4),G27*0.2,0) -> 0 | I27: 25 | J27: =G27-H27+I27 -> 1225
A28: Camila Fernandes | B28: PRESIDENCIAL | C28: =VLOOKUP(B28,CLASSES!$A$3:$B$8,2,FALSE) -> 380 | D28: 46118 | E28: 46124 | F28: =E28-D28 -> 6 | G28: =C28*F28 -> 2280 | H28: =IF(AND(B28="PRESIDENCIAL",F28>4),G28*0.2,0) -> 456 | I28: 20 | J28: =G28-H28+I28 -> 1844
A29: Amanda Ribeiro | B29: STANDART | C29: =VLOOKUP(B29,CLASSES!$A$3:$B$8,2,FALSE) -> 110 | D29: 46118 | E29: 46119 | F29: =E29-D29 -> 1 | G29: =C29*F29 -> 110 | H29: =IF(AND(B29="PRESIDENCIAL",F29>4),G29*0.2,0) -> 0 | I29: 20 | J29: =G29-H29+I29 -> 130
A30: Murilo Bastos | B30: PRESIDENCIAL | C30: =VLOOKUP(B30,CLASSES!$A$3:$B$8,2,FALSE) -> 380 | D30: 46119 | E30: 46120 | F30: =E30-D30 -> 1 | G30: =C30*F30 -> 380 | H30: =IF(AND(B30="PRESIDENCIAL",F30>4),G30*0.2,0) -> 0 | I30: 30 | J30: =G30-H30+I30 -> 410
A31: Valéria Noronha | B31: POPULAR | C31: =VLOOKUP(B31,CLASSES!$A$3:$B$8,2,FALSE) -> 90 | D31: 46119 | E31: 46120 | F31: =E31-D31 -> 1 | G31: =C31*F31 -> 90 | H31: =IF(AND(B31="PRESIDENCIAL",F31>4),G31*0.2,0) -> 0 | I31: 30 | J31: =G31-H31+I31 -> 120
A32: Diego Carvalho | B32: POPULAR | C32: =VLOOKUP(B32,CLASSES!$A$3:$B$8,2,FALSE) -> 90 | D32: 46119 | E32: 46121 | F32: =E32-D32 -> 2 | G32: =C32*F32 -> 180 | H32: =IF(AND(B32="PRESIDENCIAL",F32>4),G32*0.2,0) -> 0 | I32: 30 | J32: =G32-H32+I32 -> 210
A33: Larissa Barbosa | B33: STANDART | C33: =VLOOKUP(B33,CLASSES!$A$3:$B$8,2,FALSE) -> 110 | D33: 46119 | E33: 46125 | F33: =E33-D33 -> 6 | G33: =C33*F33 -> 660 | H33: =IF(AND(B33="PRESIDENCIAL",F33>4),G33*0.2,0) -> 0 | I33: 25 | J33: =G33-H33+I33 -> 685
A34: Daniel Martins | B34: ALTA | C34: =VLOOKUP(B34,CLASSES!$A$3:$B$8,2,FALSE) -> 120 | D34: 46119 | E34: 46120 | F34: =E34-D34 -> 1 | G34: =C34*F34 -> 120 | H34: =IF(AND(B34="PRESIDENCIAL",F34>4),G34*0.2,0) -> 0 | I34: 30 | J34: =G34-H34+I34 -> 150
A35: Nádia Severo | B35: STANDART | C35: =VLOOKUP(B35,CLASSES!$A$3:$B$8,2,FALSE) -> 110 | D35: 46120 | E35: 46121 | F35: =E35-D35 -> 1 | G35: =C35*F35 -> 110 | H35: =IF(AND(B35="PRESIDENCIAL",F35>4),G35*0.2,0) -> 0 | I35: 0 | J35: =G35-H35+I35 -> 110
A36: Gustavo Nunes | B36: ALTA | C36: =VLOOKUP(B36,CLASSES!$A$3:$B$8,2,FALSE) -> 120 | D36: 46120 | E36: 46126 | F36: =E36-D36 -> 6 | G36: =C36*F36 -> 720 | H36: =IF(AND(B36="PRESIDENCIAL",F36>4),G36*0.2,0) -> 0 | I36: 35 | J36: =G36-H36+I36 -> 755
A37: Patrícia Teixeira | B37: EXECUTIVA | C37: =VLOOKUP(B37,CLASSES!$A$3:$B$8,2,FALSE) -> 170 | D37: 46120 | E37: 46124 | F37: =E37-D37 -> 4 | G37: =C37*F37 -> 680 | H37: =IF(AND(B37="PRESIDENCIAL",F37>4),G37*0.2,0) -> 0 | I37: 10 | J37: =G37-H37+I37 -> 690
... A40: Silvana Peçanha | B40: EXECUTIVA | C40: =VLOOKUP(B40,CLASSES!$A$3:$B$8,2,FALSE) -> 170 | D40: 46121 | E40: 46122 | F40: =E40-D40 -> 1 | G40: =C40*F40 -> 170 | H40: =IF(AND(B40="PRESIDENCIAL",F40>4),G40*0.2,0) -> 0 | I40: 5 | J40: =G40-H40+I40 -> 175
A41: André Lima | B41: DOUBLE | C41: =VLOOKUP(B41,CLASSES!$A$3:$B$8,2,FALSE) -> 240 | D41: 46121 | E41: 46127 | F41: =E41-D41 -> 6 | G41: =C41*F41 -> 1440 | H41: =IF(AND(B41="PRESIDENCIAL",F41>4),G41*0.2,0) -> 0 | I41: 10 | J41: =G41-H41+I41 -> 1450 | S41: João Gabriel Spegiorin Maciel
A42: Bianca Lopes | B42: PRESIDENCIAL | C42: =VLOOKUP(B42,CLASSES!$A$3:$B$8,2,FALSE) -> 380 | D42: 46121 | E42: 46128 | F42: =E42-D42 -> 7 | G42: =C42*F42 -> 2660 | H42: =IF(AND(B42="PRESIDENCIAL",F42>4),G42*0.2,0) -> 532 | I42: 0 | J42: =G42-H42+I42 -> 2128 | S42: João Victor
A43: Rafael Duarte | B43: DOUBLE | C43: =VLOOKUP(B43,CLASSES!$A$3:$B$8,2,FALSE) -> 240 | D43: 46121 | E43: 46122 | F43: =E43-D43 -> 1 | G43: =C43*F43 -> 240 | H43: =IF(AND(B43="PRESIDENCIAL",F43>4),G43*0.2,0) -> 0 | I43: 35 | J43: =G43-H43+I43 -> 275 | S43: Kaio Levi Pollhein
A44: Lucas Souza | B44: DOUBLE | C44: =VLOOKUP(B44,CLASSES!$A$3:$B$8,2,FALSE) -> 240 | D44: 46122 | E44: 46125 | F44: =E44-D44 -> 3 | G44: =C44*F44 -> 720 | H44: =IF(AND(B44="PRESIDENCIAL",F44>4),G44*0.2,0) -> 0 | I44: 0 | J44: =G44-H44+I44 -> 720 | S44: Lara Taciana
A45: Marco Aurélio | B45: PRESIDENCIAL | C45: =VLOOKUP(B45,CLASSES!$A$3:$B$8,2,FALSE) -> 380 | D45: 46122 | E45: 46125 | F45: =E45-D45 -> 3 | G45: =C45*F45 -> 1140 | H45: =IF(AND(B45="PRESIDENCIAL",F45>4),G45*0.2,0) -> 0 | I45: 30 | J45: =G45-H45+I45 -> 1170 | S45: Leonardo Muller Mandel
A46: MARIA | B46: POPULAR | C46: =VLOOKUP(B46,CLASSES!$A$3:$B$8,2,FALSE) -> 90 | D46: 46122 | E46: 46125 | F46: =E46-D46 -> 3 | G46: =C46*F46 -> 270 | H46: =IF(AND(B46="PRESIDENCIAL",F46>4),G46*0.2,0) -> 0 | I46: 0 | J46: =G46-H46+I46 -> 270 | S46: Letícia Gomes
A47: Maria Clara Bardt Borges | B47: STANDART | C47: =VLOOKUP(B47,CLASSES!$A$3:$B$8,2,FALSE) -> 110 | D47: 46122 | E47: 46125 | F47: =E47-D47 -> 3 | G47: =C47*F47 -> 330 | H47: =IF(AND(B47="PRESIDENCIAL",F47>4),G47*0.2,0) -> 0 | I47: 5 | J47: =G47-H47+I47 -> 335 | S47: Lucas Souza
A48: Pâmela Dorneles | B48: ALTA | C48: =VLOOKUP(B48,CLASSES!$A$3:$B$8,2,FALSE) -> 120 | D48: 46122 | E48: 46123 | F48: =E48-D48 -> 1 | G48: =C48*F48 -> 120 | H48: =IF(AND(B48="PRESIDENCIAL",F48>4),G48*0.2,0) -> 0 | I48: 0 | J48: =G48-H48+I48 -> 120 | S48: Luis Gustavo
A49: Túlio Guimarães | B49: EXECUTIVA | C49: =VLOOKUP(B49,CLASSES!$A$3:$B$8,2,FALSE) -> 170 | D49: 46122 | E49: 46123 | F49: =E49-D49 -> 1 | G49: =C49*F49 -> 170 | H49: =IF(AND(B49="PRESIDENCIAL",F49>4),G49*0.2,0) -> 0 | I49: 5 | J49: =G49-H49+I49 -> 175 | S49: Luiz Octávio Isolani Theis
A50: Eduardo Freitas | B50: POPULAR | C50: =VLOOKUP(B50,CLASSES!$A$3:$B$8,2,FALSE) -> 90 | D50: 46122 | E50: 46124 | F50: =E50-D50 -> 2 | G50: =C50*F50 -> 180 | H50: =IF(AND(B50="PRESIDENCIAL",F50>4),G50*0.2,0) -> 0 | I50: 5 | J50: =G50-H50+I50 -> 185 | S50: Marco Aurélio
A51: Renata Moreira | B51: STANDART | C51: =VLOOKUP(B51,CLASSES!$A$3:$B$8,2,FALSE) -> 110 | D51: 46122 | E51: 46129 | F51: =E51-D51 -> 7 | G51: =C51*F51 -> 770 | H51: =IF(AND(B51="PRESIDENCIAL",F51>4),G51*0.2,0) -> 0 | I51: 0 | J51: =G51-H51+I51 -> 770 | S51: Maria Clara Bardt Borges
A52: Juliane Castro | B52: PRESIDENCIAL | C52: =VLOOKUP(B52,CLASSES!$A$3:$B$8,2,FALSE) -> 380 | D52: 46122 | E52: 46123 | F52: =E52-D52 -> 1 | G52: =C52*F52 -> 380 | H52: =IF(AND(B52="PRESIDENCIAL",F52>4),G52*0.2,0) -> 0 | I52: 20 | J52: =G52-H52+I52 -> 400 | S52: Martin Francisco
...

Sheet ESTATÍSTICAS
A1: ESTATÍSTICAS
A2: Estatísticas | B2: Valores
A3: QUANTIDADE DE HÓSPEDAGENS REALIZADAS EM ABRIL | B3: =COUNTIFS(CONTROLE!$D$4:$D$158,">=01/04/2026",CONTROLE!$C$4:$C$158,"<=30/04/2026") -> 155
A4: MAIOR GANHO POR HOSPÉDE NO FRIGOBAR | B4: =COUNTIFS(CONTROLE!$D$4:$D$158,">=01/04/2026",CONTROLE!$C$4:$C$158,"<=30/04/2026") -> 155
A5: MAIOR GANHO POR DIA NO FRIGOBAR | B5: =COUNTIFS(CONTROLE!$D$4:$D$158,">=01/04/2026",CONTROLE!$C$4:$C$158,"<=30/04/2026") -> 155
A6: MAIOR GANHO POR HOPÉDE COM DIÁRIAS | B6: =COUNTIFS(CONTROLE!$D$4:$D$158,">=01/04/2026",CONTROLE!$C$4:$C$158,"<=30/04/2026") -> 155
A7: MENOR GANHO POR HOPÉDE COM DIÁRIAS | B7: =COUNTIFS(CONTROLE!$D$4:$D$158,">=01/04/2026",CONTROLE!$C$4:$C$158,"<=30/04/2026") -> 155
A8: MÉDIA DE GASTOS POR HOPÉDE COM FRIGOBAR | B8: =COUNTIFS(CONTROLE!$D$4:$D$158,">=01/04/2026",CONTROLE!$C$4:$C$158,"<=30/04/2026") -> 155
A9: MÉDIA DO TOTAL DAS HOSPEDAGENS | B9: =COUNTIFS(CONTROLE!$D$4:$D$158,">=01/04/2026",CONTROLE!$C$4:$C$158,"<=30/04/2026") -> 155
A10: MÉDIA DO TOTAL DAS DIÁRIAS | B10: =COUNTIFS(CONTROLE!$D$4:$D$158,">=01/04/2026",CONTROLE!$C$4:$C$158,"<=30/04/2026") -> 155
A12: Média de HOSPEDAGEM por classe:
A13: Classe | B13: Hospedagem
A14: POPULAR | B14: 350.36
A15: STANDART | B15: 460.37
A16: ALTA | B16: 406.96
A17: EXECUTIVA | B17: 510
A18: DOUBLE | B18: 1200
A19: PRESIDENCIAL | B19: 1881.9
A21: Hospedagem por classe:
A22: Classe | B22: Faturamento
A23: POPULAR
A24: STANDART
A25: ALTA
A26: EXECUTIVA
A27: DOUBLE
A28: PRESIDENCIAL

Sheet Planilha1
A1: DASHBOARD
B4: =ESTATÍSTICAS!B3 -> 155 | D4: =Tabela2[[#This Row],[Valores]] -> 155 | F4: =ESTATÍSTICAS!B5 -> 155 | H4: =ESTATÍSTICAS!B6 -> 155
B7: =Tabela2[[#This Row],[Valores]] -> 155 | D7: =ESTATÍSTICAS!B8 -> 155 | F7: =ESTATÍSTICAS!B9 -> 155 | H7: =ESTATÍSTICAS!B10 -> 155

Sheet CLASSES
A1: TABELA DE CLASSES
A2: CLASSE | B2: VALOR R$
A3: POPULAR | B3: 90
A4: STANDART | B4: 110
A5: ALTA | B5: 120
A6: EXECUTIVA | B6: 170
A7: DOUBLE | B7: 240
A8: PRESIDENCIAL | B8: 380
